Traceback (most recent call last):
  File "/usr/local/lib/python3.11/dist-packages/jupyter_cache/executors/utils.py", line 58, in single_nb_execution
    executenb(
  File "/usr/local/lib/python3.11/dist-packages/nbclient/client.py", line 1314, in execute
    return NotebookClient(nb=nb, resources=resources, km=km, **kwargs).execute()
           ^^^^^^^^^^^^^^^^^^^^^^^^^^^^^^^^^^^^^^^^^^^^^^^^^^^^^^^^^^^^^^^^^^^^^
  File "/usr/local/lib/python3.11/dist-packages/jupyter_core/utils/__init__.py", line 165, in wrapped
    return loop.run_until_complete(inner)
           ^^^^^^^^^^^^^^^^^^^^^^^^^^^^^^
  File "/usr/lib/python3.11/asyncio/base_events.py", line 654, in run_until_complete
    return future.result()
           ^^^^^^^^^^^^^^^
  File "/usr/local/lib/python3.11/dist-packages/nbclient/client.py", line 709, in async_execute
    await self.async_execute_cell(
  File "/usr/local/lib/python3.11/dist-packages/nbclient/client.py", line 1062, in async_execute_cell
    await self._check_raise_for_error(cell, cell_index, exec_reply)
  File "/usr/local/lib/python3.11/dist-packages/nbclient/client.py", line 918, in _check_raise_for_error
    raise CellExecutionError.from_cell_and_msg(cell, exec_reply_content)
nbclient.exceptions.CellExecutionError: An error occurred while executing the following cell:
------------------
import pandas as pd

import plotly.graph_objs as go

from ostk.mathematics.object import RealInterval

from ostk.physics import Environment
from ostk.physics.unit import Length
from ostk.physics.unit import Angle
from ostk.physics.time import Scale
from ostk.physics.time import Instant
from ostk.physics.time import Duration
from ostk.physics.time import Interval
from ostk.physics.time import DateTime
from ostk.physics.time import Time
from ostk.physics.coordinate.spherical import LLA
from ostk.physics.coordinate import Position
from ostk.physics.coordinate import Frame

from ostk.astrodynamics import Trajectory
from ostk.astrodynamics.trajectory import Orbit
from ostk.astrodynamics.trajectory.orbit.model import Kepler
from ostk.astrodynamics.trajectory.orbit.model.kepler import COE
from ostk.astrodynamics.trajectory.orbit.model import SGP4
from ostk.astrodynamics.trajectory.orbit.model.sgp4 import TLE
from ostk.astrodynamics.access import Generator as AccessGenerator
from ostk.astrodynamics.utilities import compute_trajectory_geometry
from ostk.astrodynamics.utilities import compute_time_lla_aer_state
------------------


[0;31m---------------------------------------------------------------------------[0m
[0;31mImportError[0m                               Traceback (most recent call last)
Cell [0;32mIn[1], line 28[0m
[1;32m     26[0m [38;5;28;01mfrom[39;00m [38;5;21;01mostk[39;00m[38;5;21;01m.[39;00m[38;5;21;01mastrodynamics[39;00m[38;5;21;01m.[39;00m[38;5;21;01maccess[39;00m [38;5;28;01mimport[39;00m Generator [38;5;28;01mas[39;00m AccessGenerator
[1;32m     27[0m [38;5;28;01mfrom[39;00m [38;5;21;01mostk[39;00m[38;5;21;01m.[39;00m[38;5;21;01mastrodynamics[39;00m[38;5;21;01m.[39;00m[38;5;21;01mutilities[39;00m [38;5;28;01mimport[39;00m compute_trajectory_geometry
[0;32m---> 28[0m [38;5;28;01mfrom[39;00m [38;5;21;01mostk[39;00m[38;5;21;01m.[39;00m[38;5;21;01mastrodynamics[39;00m[38;5;21;01m.[39;00m[38;5;21;01mutilities[39;00m [38;5;28;01mimport[39;00m compute_time_lla_aer_state

[0;31mImportError[0m: cannot import name 'compute_time_lla_aer_state' from 'ostk.astrodynamics.utilities' (/usr/local/lib/python3.11/dist-packages/ostk/astrodynamics/utilities.py)

