Traceback (most recent call last):
  File "/usr/local/lib/python3.11/dist-packages/jupyter_cache/executors/utils.py", line 58, in single_nb_execution
    executenb(
  File "/usr/local/lib/python3.11/dist-packages/nbclient/client.py", line 1319, in execute
    return NotebookClient(nb=nb, resources=resources, km=km, **kwargs).execute()
           ^^^^^^^^^^^^^^^^^^^^^^^^^^^^^^^^^^^^^^^^^^^^^^^^^^^^^^^^^^^^^^^^^^^^^
  File "/usr/local/lib/python3.11/dist-packages/jupyter_core/utils/__init__.py", line 165, in wrapped
    return loop.run_until_complete(inner)
           ^^^^^^^^^^^^^^^^^^^^^^^^^^^^^^
  File "/usr/lib/python3.11/asyncio/base_events.py", line 654, in run_until_complete
    return future.result()
           ^^^^^^^^^^^^^^^
  File "/usr/local/lib/python3.11/dist-packages/nbclient/client.py", line 709, in async_execute
    await self.async_execute_cell(
  File "/usr/local/lib/python3.11/dist-packages/nbclient/client.py", line 1062, in async_execute_cell
    await self._check_raise_for_error(cell, cell_index, exec_reply)
  File "/usr/local/lib/python3.11/dist-packages/nbclient/client.py", line 918, in _check_raise_for_error
    raise CellExecutionError.from_cell_and_msg(cell, exec_reply_content)
nbclient.exceptions.CellExecutionError: An error occurred while executing the following cell:
------------------
azimuth_range = RealInterval.closed(0.0, 360.0)  # [deg]
elevation_range = RealInterval.closed(20.0, 90.0)  # [deg]
range_range = RealInterval.closed(0.0, 10000e3)  # [m]

# Access generator with Azimuth-Range-Elevation constraints

access_generator = AccessGenerator.aer_ranges(
    azimuth_range, elevation_range, range_range, environment
)
------------------


[0;31m---------------------------------------------------------------------------[0m
[0;31mAttributeError[0m                            Traceback (most recent call last)
Cell [0;32mIn[16], line 7[0m
[1;32m      3[0m range_range [38;5;241m=[39m RealInterval[38;5;241m.[39mclosed([38;5;241m0.0[39m, [38;5;241m10000e3[39m)  [38;5;66;03m# [m][39;00m
[1;32m      5[0m [38;5;66;03m# Access generator with Azimuth-Range-Elevation constraints[39;00m
[0;32m----> 7[0m access_generator [38;5;241m=[39m [43mAccessGenerator[49m[38;5;241;43m.[39;49m[43maer_ranges[49m(
[1;32m      8[0m     azimuth_range, elevation_range, range_range, environment
[1;32m      9[0m )

[0;31mAttributeError[0m: type object 'ostk.astrodynamics.access.Generator' has no attribute 'aer_ranges'

