Traceback (most recent call last):
  File "/usr/local/lib/python3.11/dist-packages/jupyter_core/utils/__init__.py", line 154, in wrapped
    asyncio.get_running_loop()
RuntimeError: no running event loop

During handling of the above exception, another exception occurred:

Traceback (most recent call last):
  File "/usr/local/lib/python3.11/dist-packages/jupyter_cache/executors/utils.py", line 58, in single_nb_execution
    executenb(
  File "/usr/local/lib/python3.11/dist-packages/nbclient/client.py", line 1319, in execute
    return NotebookClient(nb=nb, resources=resources, km=km, **kwargs).execute()
           ^^^^^^^^^^^^^^^^^^^^^^^^^^^^^^^^^^^^^^^^^^^^^^^^^^^^^^^^^^^^^^^^^^^^^
  File "/usr/local/lib/python3.11/dist-packages/jupyter_core/utils/__init__.py", line 158, in wrapped
    return loop.run_until_complete(inner)
           ^^^^^^^^^^^^^^^^^^^^^^^^^^^^^^
  File "/usr/lib/python3.11/asyncio/base_events.py", line 654, in run_until_complete
    return future.result()
           ^^^^^^^^^^^^^^^
  File "/usr/local/lib/python3.11/dist-packages/nbclient/client.py", line 709, in async_execute
    await self.async_execute_cell(
  File "/usr/local/lib/python3.11/dist-packages/nbclient/client.py", line 1062, in async_execute_cell
    await self._check_raise_for_error(cell, cell_index, exec_reply)
  File "/usr/local/lib/python3.11/dist-packages/nbclient/client.py", line 918, in _check_raise_for_error
    raise CellExecutionError.from_cell_and_msg(cell, exec_reply_content)
nbclient.exceptions.CellExecutionError: An error occurred while executing the following cell:
------------------
states = propagator.calculate_states_at(state, instants)
------------------


[0;31m---------------------------------------------------------------------------[0m
[0;31mTypeError[0m                                 Traceback (most recent call last)
Cell [0;32mIn[9], line 1[0m
[0;32m----> 1[0m states [38;5;241m=[39m [43mpropagator[49m[38;5;241;43m.[39;49m[43mcalculate_states_at[49m[43m([49m[43mstate[49m[43m,[49m[43m [49m[43minstants[49m[43m)[49m

Cell [0;32mIn[3], line 31[0m, in [0;36mThrusterDynamics.compute_contribution[0;34m(self, instant, x, frame)[0m
[1;32m     28[0m acceleration_vnc [38;5;241m=[39m np[38;5;241m.[39marray([[38;5;241m1[39m, [38;5;241m0[39m, [38;5;241m0[39m]) [38;5;241m*[39m [38;5;28mself[39m[38;5;241m.[39m_thrust [38;5;241m/[39m mass
[1;32m     30[0m [38;5;66;03m# convert to GCRF[39;00m
[0;32m---> 31[0m local_orbital_frame [38;5;241m=[39m [43mLocalOrbitalFrameFactory[49m[38;5;241;43m.[39;49m[43mVNC[49m[43m([49m[43mFrame[49m[38;5;241;43m.[39;49m[43mGCRF[49m[43m([49m[43m)[49m[43m)[49m[38;5;241;43m.[39;49m[43mgenerate_frame[49m[43m([49m
[1;32m     32[0m [43m    [49m[43minstant[49m[43m,[49m[43m [49m[43mx[49m[43m[[49m[43m:[49m[38;5;241;43m3[39;49m[43m][49m[43m,[49m[43m [49m[43mx[49m[43m[[49m[38;5;241;43m3[39;49m[43m:[49m[38;5;241;43m6[39;49m[43m][49m
[1;32m     33[0m [43m[49m[43m)[49m
[1;32m     34[0m q_GCRF_to_VNC [38;5;241m=[39m local_orbital_frame[38;5;241m.[39mget_transform_to(
[1;32m     35[0m     Frame[38;5;241m.[39mGCRF(), instant
[1;32m     36[0m )[38;5;241m.[39mget_orientation()
[1;32m     37[0m q_GCRF_to_VNC[38;5;241m.[39mnormalize()

[0;31mTypeError[0m: generate_frame(): incompatible function arguments. The following argument types are supported:
    1. (self: ostk.astrodynamics.trajectory.LocalOrbitalFrameFactory, state: ostk::astrodynamics::trajectory::State) -> ostk.physics.coordinate.Frame

Invoked with: <ostk.astrodynamics.trajectory.LocalOrbitalFrameFactory object at 0x7f893f351bf0>, 2000-01-01 11:58:55.816 [UTC], array([7000000.,       0.,       0.]), array([   0.        , 5335.86545062, 5335.86545062])

