Traceback (most recent call last):
  File "/usr/local/lib/python3.11/dist-packages/jupyter_cache/executors/utils.py", line 58, in single_nb_execution
    executenb(
  File "/usr/local/lib/python3.11/dist-packages/nbclient/client.py", line 1319, in execute
    return NotebookClient(nb=nb, resources=resources, km=km, **kwargs).execute()
           ^^^^^^^^^^^^^^^^^^^^^^^^^^^^^^^^^^^^^^^^^^^^^^^^^^^^^^^^^^^^^^^^^^^^^
  File "/usr/local/lib/python3.11/dist-packages/jupyter_core/utils/__init__.py", line 165, in wrapped
    return loop.run_until_complete(inner)
           ^^^^^^^^^^^^^^^^^^^^^^^^^^^^^^
  File "/usr/lib/python3.11/asyncio/base_events.py", line 654, in run_until_complete
    return future.result()
           ^^^^^^^^^^^^^^^
  File "/usr/local/lib/python3.11/dist-packages/nbclient/client.py", line 709, in async_execute
    await self.async_execute_cell(
  File "/usr/local/lib/python3.11/dist-packages/nbclient/client.py", line 1062, in async_execute_cell
    await self._check_raise_for_error(cell, cell_index, exec_reply)
  File "/usr/local/lib/python3.11/dist-packages/nbclient/client.py", line 918, in _check_raise_for_error
    raise CellExecutionError.from_cell_and_msg(cell, exec_reply_content)
nbclient.exceptions.CellExecutionError: An error occurred while executing the following cell:
------------------
access_generator = AccessGenerator.aer_ranges(
    azimuth_range=RealInterval.closed(0.0, 360.0),
    elevation_range=RealInterval.closed(20.0, 90.0),
    range_range=RealInterval.closed(0.0, 10000e3),
    environment=environment,
)

accesses = access_generator.compute_accesses(
    interval=interval,
    from_trajectory=Trajectory.position(target_position),
    to_trajectory=orbit,
)

access = accesses[0]
------------------


[0;31m---------------------------------------------------------------------------[0m
[0;31mAttributeError[0m                            Traceback (most recent call last)
Cell [0;32mIn[6], line 1[0m
[0;32m----> 1[0m access_generator [38;5;241m=[39m [43mAccessGenerator[49m[38;5;241;43m.[39;49m[43maer_ranges[49m(
[1;32m      2[0m     azimuth_range[38;5;241m=[39mRealInterval[38;5;241m.[39mclosed([38;5;241m0.0[39m, [38;5;241m360.0[39m),
[1;32m      3[0m     elevation_range[38;5;241m=[39mRealInterval[38;5;241m.[39mclosed([38;5;241m20.0[39m, [38;5;241m90.0[39m),
[1;32m      4[0m     range_range[38;5;241m=[39mRealInterval[38;5;241m.[39mclosed([38;5;241m0.0[39m, [38;5;241m10000e3[39m),
[1;32m      5[0m     environment[38;5;241m=[39menvironment,
[1;32m      6[0m )
[1;32m      8[0m accesses [38;5;241m=[39m access_generator[38;5;241m.[39mcompute_accesses(
[1;32m      9[0m     interval[38;5;241m=[39minterval,
[1;32m     10[0m     from_trajectory[38;5;241m=[39mTrajectory[38;5;241m.[39mposition(target_position),
[1;32m     11[0m     to_trajectory[38;5;241m=[39morbit,
[1;32m     12[0m )
[1;32m     14[0m access [38;5;241m=[39m accesses[[38;5;241m0[39m]

[0;31mAttributeError[0m: type object 'ostk.astrodynamics.access.Generator' has no attribute 'aer_ranges'

